Workbook

Sheet Quarterly Update Checklist
B1: Tasks to be completed for a Quarterly Update | C1: Complete | G1: Notes
B2: Updated Scenarios | C2: QLD | D2: NSW | E2: VIC | F2: SA
A3: FALSE | B3: - Updated scenario data has been copied into input deck | C3: FALSE | D3: FALSE | E3: FALSE | F3: FALSE
B4: Releasable User Guides
A5: FALSE | B5: - Updated RUG list with new RUGs | C5: FALSE | D5: FALSE | E5: FALSE | F5: FALSE | G5: NA no recent RUG download
A6: FALSE | B6: - Each RUG has been modelled per latest timing and details | C6: FALSE | D6: FALSE | E6: FALSE | F6: FALSE | G6: NA no recent RUG download
A7: FALSE | B7: - Each GCE has reviewed their respective states' RUGs | C7: FALSE | D7: FALSE | E7: FALSE | F7: FALSE | G7: NA no recent RUG download
B8: Grid Line Loss List
A9: FALSE | B9: - Updated GLL list with new project data from Commercial team | C9: FALSE | D9: FALSE | E9: FALSE | F9: FALSE
A10: FALSE | B10: - Each project has been modelled per latest timing and details | C10: FALSE | D10: FALSE | E10: FALSE | F10: FALSE | G10: Check this via GLL list
A11: FALSE | B11: - Each GCE has reviewed their respective states' projects | C11: FALSE | D11: FALSE | E11: FALSE | F11: FALSE | G11: Check this via GLL list
B12: Network Augmentations
A13: FALSE | B13: - Each augmentation has been modelled per latest timing and details | C13: FALSE | D13: FALSE | E13: FALSE | F13: FALSE | G13: Check this via Scenario Checklist
A14: FALSE | B14: - Buses and projects affected have been reviewed and updated accordingly | C14: FALSE | D14: FALSE | E14: FALSE | F14: FALSE
A15: FALSE | B15: - Each GCE has reviewed their respective states' augmentations | C15: FALSE | D15: FALSE | E15: FALSE | F15: FALSE | G15: Check this via Scenario Checklist
B16: Coal Plant Closures
A17: FALSE | B17: - Each project has been modelled per latest timing and details | C17: FALSE | D17: FALSE | E17: FALSE | F17: FALSE | G17: Check this via Scenario Checklist
A18: FALSE | B18: - Each GCE has reviewed their respective states' retirements | C18: FALSE | D18: FALSE | E18: FALSE | F18: FALSE | G18: Check this via Scenario Checklist
B19: Gas Plant Buildout
A20: FALSE | B20: - Manual buildout of gas (bringing online / retirements) matches that of the correct scenario's gas buildout outlined | C20: FALSE | D20: FALSE | E20: FALSE | F20: FALSE | G20: May be situations where old gas plants must be modified to increase overall growth.
A21: FALSE | B21: - Each GCE has reviewed their respective states' gas buildout | C21: FALSE | D21: FALSE | E21: FALSE | F21: FALSE | G21: Check this via Scenario Checklist
B22: Cutsets
A23: FALSE | B23: - Cutset commission dates match with their respective network augmentation | C23: FALSE | D23: FALSE | E23: FALSE | F23: FALSE | G23: Check this via Scenario Checklist
B24: State Buildout Summary
A25: FALSE | B25: - If scenario is updated, data is copied into correct scenario sheet | C25: FALSE | D25: FALSE | E25: FALSE | F25: FALSE
A26: FALSE | B26: - Storage/battery/solar buildout calculations match data buildout | C26: FALSE | D26: FALSE | E26: FALSE | F26: FALSE
B27: Notional Buildout
A28: FALSE | B28: - 'Inservice' column is TRUE for all buses within NotionalGenCalc0 sheet | C28: FALSE | D28: FALSE | E28: FALSE | F28: FALSE | G28: May be situations where capacity added is <1MW, which the notional buildout will not build
A29: FALSE | B29: - If the State Buildout Summary sheet has been updated, the notional buildout reflects these changes | C29: FALSE | D29: FALSE | E29: FALSE | F29: FALSE
A30: FALSE | B30: - Some REZs (~3) in each state have been reviewed by comparing notional buildout for that REZ and FuelType with the ISP Buildout Allocation sheet | C30: FALSE | D30: FALSE | E30: FALSE | F30: FALSE
B31: DER Buildout
A32: FALSE | B32: - If the State Buildout Summary sheet has been updated, the DER buildout reflects these changes | C32: FALSE | D32: FALSE | E32: FALSE | F32: FALSE
A33: FALSE | B33: - Some REZs (~3) in each state have been reviewed by comparing notional buildout for that REZ and FuelType with the DER Reallocation sheet | C33: FALSE | D33: FALSE | E33: FALSE | F33: FALSE
B34: Python Grid Model
A35: FALSE | B35: - PyCharm is set on the correct branch (main) of the grid model | C35: FALSE | D35: FALSE | E35: FALSE | F35: FALSE

Sheet Changes Tracker Q1 26
A1: Description | B1: Sheet Name | C1: Region | D1: Owner | E1: Date Added | F1: Comments
A2: Updated coal plant closures | B2: Augmentation & Closures | C2: ALL | D2: Wriece | E2: 46015
A3: Removed Borumba PHES | B3: committed PH | C3: QLD | D3: Wriece | E3: 46015
A4: Added in new rugs | B4: committed gen & Add Gen List | C4: ALL | D4: Wriece | E4: 46015
A5: Updated demand forecast | B5: mod_load | C5: ALL | D5: Wriece | E5: 46021
A6: Added in VTP projects | B6: VTP & RES dev | C6: VIC | D6: Wriece | E6: 46021
A7: Updated REZ generation capacity | B7: ISP REZ Generation Capacity (2) | C7: VIC | D7: Wriece | E7: 46021 | F7: Updated only VIC REZ generation capacity due to new VIC rezs
A8: Updated REZ Buildout | B8: Baringa RC Buildout Summary & Buildout Allocation | C8: ALL | D8: Wriece | E8: 46021 | F8: Updated all REZ buildouts. Notably VIC with the addition of new REZ's
A9: Updated REZ bus allocation | B9: REZ Bus Alloation - Bari RC | C9: VIC | D9: Wriece | E9: 46021 | F9: Updated VIC REZ build out bus allocation to reflect updated REZs
A10: Updated REZ mapping | B10: REZ Mapping | C10: VIC | D10: Wriece | E10: 46021 | F10: Updated REZ mapping sheet to reflect updated VIC REZs
A11: Organised relevant sheets to group the augmentation projects and renewable projects by NEM states | B11: Committed (Baringa Q4 25 RC) Actionable (Baringa Q4 25 RC) Retirements (Baringa RC) in-service gen committed gen RES ph4 RES dev | C11: All | D11: Frank | E11: 46029 | F11: As per discussion during Grid Workshop on 18/12.
A12: Kaban WF fuel type changed from Solar to Wind and capacity changed from 160 to 152 to match RUG | B12: Add Gen List, committed gen, REZ mapping | C12: QLD | D12: Beau | E12: 46048 | F12: Error carried through from past
A13: Exclude Jackson WF from GLL list | B13: RES dev, Add Gen List | C13: QLD | D13: Frank | E13: 46056 | F13: Updated as per latest GLL list from Carl
A14: Gladstone Project scope update | B14: Actionable (Baringa Q4 25 RC) | C14: QLD | D14: Frank | E14: 46057 | F14: Further refinement of scope in draft 2026 ISP
A15: CQ-GG cutset revision | B15: Post aug cutset | C15: QLD | D15: Frank | E15: 46059 | F15: Cutset definition revised to reflect changes to Gladstone Project scope

Sheet Changes Tracker Q2
A1: Description | B1: Sheet Name | C1: Region | D1: Owner | E1: Date Added | F1: Comments
A2: Osborne Cogen Plant retirement | B2: Retirements (Baringa RC) | C2: SA | D2: Wriece | E2: 46979 | F2: Date updated from 2026 - 2027
A3: Torrens A PS | B3: Retirements (Baringa RC) | C3: SA | D3: Wriece | E3: 46979 | F3: Included retirement of Torrens A PS
A4: WRL | B4: Augmentation & Closures | C4: VIC | D4: Wriece | E4: 46979 | F4: Updated date to Dec 2029
A5: Clements GAP BESS Gen | B5: committed gen & Add Gen List | C5: SA | D5: Wriece | E5: 46979 | F5: Updated commissioning date to 1/07/2026 and corrected profile to reference Load
A6: Mannum BESS Gen | B6: committed gen & Add Gen List | C6: SA | D6: Wriece | E6: 46979 | F6: Updated commissioning date to 1/09/2025 and corrected profile to reference load
A7: Bungama BESS | B7: committed gen & Add Gen List | C7: SA | D7: Wriece | E7: 46979 | F7: Added Bungama BESS to Bungama 275 kV
A8: Carwarp SF | B8: committed gen & Add Gen List | C8: VIC | D8: Wriece | E8: 46979 | F8: Change commissioning date to 1/07/2027
A9: Goorambat East SF | B9: committed gen & Add Gen List | C9: VIC | D9: Wriece | E9: 46979 | F9: Change commissioning date to 1/01/2027
A10: Horsham SF | B10: committed gen & Add Gen List | C10: VIC | D10: Wriece | E10: 46979 | F10: Change commissioning date to 1/01/2027
A11: Lancaster SF | B11: committed gen & Add Gen List | C11: VIC | D11: Wriece | E11: 46979 | F11: Change commissioning date to 1/11/2026
A12: Mornington BESS | B12: committed gen & Add Gen List | C12: VIC | D12: Wriece | E12: 46979 | F12: Change commissioning date to 1/07/2026
A13: Terang BESS | B13: committed gen & Add Gen List | C13: VIC | D13: Wriece | E13: 46979 | F13: Change commissioning date to 1/01/2027
... A121: Bunyip North BESS | B121: RES dev | C121: VIC | D121: Wriece | E121: 45905 | F121: Disabled AGC for gen and load

Sheet New RUG List Q4
A1: New RUG List released from AEMO
A3: Name | B3: Tech | C3: Region | D3: Export Limit | E3: Commissioning Start | F3: REZ | I3: Added? | J3: Checked | K3: Responsible | L3: Reviewed by | M3: Comments
I4: FALSE | J4: FALSE
I5: FALSE | J5: FALSE
A6: New Baringa Renewable Plant Assumptions Q4 25 | H6: Changes
A7: Project Name | B7: Tech | C7: Region | D7: Capacity | E7: Commercial Use Date | F7: REZ | I7: Added? | J7: Checked | K7: Responsible | L7: Reviewed by | M7: Comments
A8: Adelaide Desalination Plant | B8: Solar | C8: SA | D8: 25 | E8: Existing | F8: S3 | G8: =VLOOKUP(A8,$A$342:$A$427,1,FALSE) -> #N/A | H8: =VLOOKUP(A8,$A$342:$E$427,5,FALSE) -> #N/A | I8: FALSE | J8: FALSE
A9: Adelaide Desalination Plant | B9: Storage - Battery | C9: SA | D9: 8 MW / 13 MWh | E9: Existing | F9: S3 | G9: =VLOOKUP(A9,$A$342:$A$427,1,FALSE) -> #N/A | H9: =VLOOKUP(A9,$A$342:$E$427,5,FALSE) -> #N/A | I9: FALSE | J9: FALSE
A10: Aldoga Solar Farm | B10: Solar | C10: QLD | D10: 380 | E10: Existing | F10: Q6 | G10: =VLOOKUP(A10,$A$342:$A$427,1,FALSE) -> Aldoga Solar Farm | H10: =VLOOKUP(A10,$A$342:$E$427,5,FALSE) -> 45870 | I10: TRUE | J10: TRUE | L10: Beau
A11: Ararat Wind Farm | B11: Wind | C11: VIC | D11: 241 | E11: Existing | F11: V3 | G11: =VLOOKUP(A11,$A$342:$A$427,1,FALSE) -> #N/A | H11: =VLOOKUP(A11,$A$342:$E$427,5,FALSE) -> #N/A | I11: FALSE | J11: FALSE
A12: Avonlie Solar Farm | B12: Solar | C12: NSW | D12: 190 | E12: Existing | F12: N5 | G12: =VLOOKUP(A12,$A$342:$A$427,1,FALSE) -> #N/A | H12: =VLOOKUP(A12,$A$342:$E$427,5,FALSE) -> #N/A
A13: Baking Board Solar Farm | B13: Solar | C13: QLD | D13: 15 | E13: Existing | F13: Q8 | G13: =VLOOKUP(A13,$A$342:$A$427,1,FALSE) -> #N/A | H13: =VLOOKUP(A13,$A$342:$E$427,5,FALSE) -> #N/A
A14: Bald Hills Wind Farm | B14: Wind | C14: VIC | D14: 106 | E14: Existing | F14: V5 | G14: =VLOOKUP(A14,$A$342:$A$427,1,FALSE) -> #N/A | H14: =VLOOKUP(A14,$A$342:$E$427,5,FALSE) -> #N/A
A15: Ballarat Energy Storage | B15: Storage - Battery | C15: VIC | D15: 30 MW / 30 MWh | E15: Existing | F15: V3 | G15: =VLOOKUP(A15,$A$342:$A$427,1,FALSE) -> #N/A | H15: =VLOOKUP(A15,$A$342:$E$427,5,FALSE) -> #N/A
A16: Bango Wind Farm | B16: Wind | C16: NSW | D16: 244 | E16: Existing | F16: N4 | G16: =VLOOKUP(A16,$A$342:$A$427,1,FALSE) -> #N/A | H16: =VLOOKUP(A16,$A$342:$E$427,5,FALSE) -> #N/A
A17: Bannerton Solar Park | B17: Solar | C17: VIC | D17: 88 | E17: Existing | F17: V2 | G17: =VLOOKUP(A17,$A$342:$A$427,1,FALSE) -> #N/A | H17: =VLOOKUP(A17,$A$342:$E$427,5,FALSE) -> #N/A
A18: Barcaldine Remote Community Solar Farm | B18: Solar | C18: QLD | D18: 20 | E18: Existing | F18: Q5 | G18: =VLOOKUP(A18,$A$342:$A$427,1,FALSE) -> #N/A | H18: =VLOOKUP(A18,$A$342:$E$427,5,FALSE) -> #N/A
A19: Berrybank Wind Farm - Stage 1 | B19: Wind | C19: VIC | D19: 176 | E19: Existing | F19: V4 | G19: =VLOOKUP(A19,$A$342:$A$427,1,FALSE) -> #N/A | H19: =VLOOKUP(A19,$A$342:$E$427,5,FALSE) -> #N/A
A20: Berrybank Wind Farm - Stage 2 | B20: Wind | C20: VIC | D20: 109 | E20: Existing | F20: V4 | G20: =VLOOKUP(A20,$A$342:$A$427,1,FALSE) -> #N/A | H20: =VLOOKUP(A20,$A$342:$E$427,5,FALSE) -> #N/A
A21: Beryl Solar Farm | B21: Solar | C21: NSW | D21: 87 | E21: Existing | F21: N3 | G21: =VLOOKUP(A21,$A$342:$A$427,1,FALSE) -> #N/A | H21: =VLOOKUP(A21,$A$342:$E$427,5,FALSE) -> #N/A
A22: Blayney Wind Farm | B22: Wind | C22: NSW | D22: 10 | E22: Existing | F22: N3 | G22: =VLOOKUP(A22,$A$342:$A$427,1,FALSE) -> #N/A | H22: =VLOOKUP(A22,$A$342:$E$427,5,FALSE) -> #N/A
A23: Blind Creek Solar Farm | B23: Solar | C23: NSW | D23: 300 | E23: 46539 | F23: N7 | G23: =VLOOKUP(A23,$A$342:$A$427,1,FALSE) -> #N/A | H23: =VLOOKUP(A23,$A$342:$E$427,5,FALSE) -> #N/A | I23: FALSE | J23: FALSE | M23: Added 24/12/2025
A24: Blind Creek Solar Farm - BESS | B24: Storage - Battery | C24: NSW | D24: 243 MW / 486 MWh | E24: 46722 | F24: N7 | G24: =VLOOKUP(A24,$A$342:$A$427,1,FALSE) -> #N/A | H24: =VLOOKUP(A24,$A$342:$E$427,5,FALSE) -> #N/A | I24: FALSE | J24: FALSE | M24: Added 24/12/2025
A25: Blue Grass Solar Farm | B25: Solar | C25: QLD | D25: 148 | E25: Existing | F25: Q8 | G25: =VLOOKUP(A25,$A$342:$A$427,1,FALSE) -> #N/A | H25: =VLOOKUP(A25,$A$342:$E$427,5,FALSE) -> #N/A
A26: Blyth BESS | B26: Storage - Battery | C26: SA | D26: 200 MW / 400 MWh | E26: Existing | F26: S3 | G26: =VLOOKUP(A26,$A$342:$A$427,1,FALSE) -> #N/A | H26: =VLOOKUP(A26,$A$342:$E$427,5,FALSE) -> #N/A
A27: Boco Rock Wind Farm | B27: Wind | C27: NSW | D27: 113 | E27: Existing | F27: N9 | G27: =VLOOKUP(A27,$A$342:$A$427,1,FALSE) -> #N/A | H27: =VLOOKUP(A27,$A$342:$E$427,5,FALSE) -> #N/A
A28: Bodangora Wind Farm | B28: Wind | C28: NSW | D28: 111 | E28: Existing | F28: N3 | G28: =VLOOKUP(A28,$A$342:$A$427,1,FALSE) -> #N/A | H28: =VLOOKUP(A28,$A$342:$E$427,5,FALSE) -> #N/A
A29: Bolivar Waste Water Treatment Solar Plant | B29: Solar | C29: SA | D29: 11 | E29: Existing | F29: S3 | G29: =VLOOKUP(A29,$A$342:$A$427,1,FALSE) -> #N/A | H29: =VLOOKUP(A29,$A$342:$E$427,5,FALSE) -> #N/A
A30: Bomen Solar Farm | B30: Solar | C30: NSW | D30: 100 | E30: Existing | F30: N7 | G30: =VLOOKUP(A30,$A$342:$A$427,1,FALSE) -> #N/A | H30: =VLOOKUP(A30,$A$342:$E$427,5,FALSE) -> #N/A
A31: Boulder Creek Wind Farm - stage 1 | B31: Wind | C31: QLD | D31: 228 | E31: 46753 | F31: Q6 | G31: =VLOOKUP(A31,$A$342:$A$427,1,FALSE) -> Boulder Creek Wind Farm - stage 1 | H31: =VLOOKUP(A31,$A$342:$E$427,5,FALSE) -> 46753 | I31: TRUE | J31: TRUE | L31: Beau | M31: No change required
A32: Bouldercombe BESS | B32: Storage - Battery | C32: QLD | D32: 50 MW / 100 MWh | E32: Existing | F32: Q6 | G32: =VLOOKUP(A32,$A$342:$A$427,1,FALSE) -> #N/A | H32: =VLOOKUP(A32,$A$342:$E$427,5,FALSE) -> #N/A
A33: Brendale BESS | B33: Storage - Battery | C33: QLD | D33: 205 MW / 410 MWh | E33: 46174 | G33: =VLOOKUP(A33,$A$342:$A$427,1,FALSE) -> Brendale BESS | H33: =VLOOKUP(A33,$A$342:$E$427,5,FALSE) -> 46174 | I33: TRUE | J33: TRUE | L33: Beau | M33: No change required
A34: Broadsound BESS | B34: Storage - Battery | C34: QLD | D34: 180MW / 360MWh | E34: 46388 | F34: Q4 | G34: =VLOOKUP(A34,$A$342:$A$427,1,FALSE) -> Broadsound BESS | H34: =VLOOKUP(A34,$A$342:$E$427,5,FALSE) -> 46388 | I34: TRUE | J34: TRUE | L34: Beau | M34: No change required
A35: Broadsound Solar Farm | B35: Solar | C35: QLD | D35: 296 | E35: 46235 | F35: Q4 | G35: =VLOOKUP(A35,$A$342:$A$427,1,FALSE) -> Broadsound Solar Farm | H35: =VLOOKUP(A35,$A$342:$E$427,5,FALSE) -> 46388 | I35: TRUE | J35: TRUE | L35: Beau | M35: No change required
A36: Broken Hill Battery | B36: Storage - Battery | C36: NSW | D36: 50 MW / 50 MWh | E36: Existing | F36: N4 | G36: =VLOOKUP(A36,$A$342:$A$427,1,FALSE) -> #N/A | H36: =VLOOKUP(A36,$A$342:$E$427,5,FALSE) -> #N/A
A37: Broken Hill Solar Plant | B37: Solar | C37: NSW | D37: 53 | E37: Existing | F37: N5 | G37: =VLOOKUP(A37,$A$342:$A$427,1,FALSE) -> #N/A | H37: =VLOOKUP(A37,$A$342:$E$427,5,FALSE) -> #N/A
A38: Bulabul BESS | B38: Storage - Battery | C38: NSW | D38: 300 MW / 600 MWh | E38: 46447 | G38: =VLOOKUP(A38,$A$342:$A$427,1,FALSE) -> #N/A | H38: =VLOOKUP(A38,$A$342:$E$427,5,FALSE) -> #N/A | I38: FALSE | J38: FALSE | M38: Added 24/12/2025
A39: Bulgana Green Power Hub - BESS | B39: Storage - Battery | C39: VIC | D39: 20 MW / 34 MWh | E39: Existing | F39: V3 | G39: =VLOOKUP(A39,$A$342:$A$427,1,FALSE) -> #N/A | H39: =VLOOKUP(A39,$A$342:$E$427,5,FALSE) -> #N/A
A40: Bulgana Wind Farm | B40: Wind | C40: VIC | D40: 204 | E40: Existing | F40: V3 | G40: =VLOOKUP(A40,$A$342:$A$427,1,FALSE) -> #N/A | H40: =VLOOKUP(A40,$A$342:$E$427,5,FALSE) -> #N/A
A41: Bundaberg Solar Farm | B41: Solar | C41: QLD | D41: 78 | E41: 46082 | F41: Q7 | G41: =VLOOKUP(A41,$A$342:$A$427,1,FALSE) -> Bundaberg Solar Farm | H41: =VLOOKUP(A41,$A$342:$E$427,5,FALSE) -> 45992 | I41: TRUE | J41: TRUE | L41: Beau | M41: Date changed on 24/12/2025
...

Sheet New RUG List Q2
A1: New RUG List
A3: Name | B3: Tech | C3: Region | D3: Export Limit | E3: Commissioning Start | F3: REZ | H3: Added? | I3: Checked | J3: Responsible | K3: Reviewed by | L3: Comments
A4: Bungama BESS | B4: Storage - Battery | C4: SA | D4: 150 MW / 300 MWh | F4: S5 | H4: TRUE | I4: FALSE
A5: Lockyer Valley Energy Project | B5: Gas | C5: QLD | D5: 116 MW | E5: 46357 | F5: Q8 | H5: TRUE | I5: TRUE | J5: Frank W | K5: Wriece M | L5: WM - Have we removed from the gas buildout after adding this in?
A6: Swanbank BESS | B6: Storage - Battery | C6: QLD | D6: 250 MW / 500 MWh | E6: 46082 | F6: Q8 | H6: TRUE | I6: TRUE | J6: Frank W | K6: Wriece M
A7: HAY SUN FARM | B7: Solar Farm | C7: NSW | D7: 110 MW | F7: N5 | H7: TRUE | I7: TRUE | J7: Jack S | K7: Wriece M
A8: Snowy 2.0 | B8: Hydro (long storage 16hr equivalent) | C8: NSW | D8: 2000 MW | F8: N7 | H8: TRUE | I8: TRUE | J8: Jack S | K8: Wriece M | L8: Likely already modelled please check?
A9: Maryvale Energy from Waste | B9: Gas | C9: VIC | D9: 70 MW | F9: V5 | H9: TRUE | I9: TRUE | J9: Wriece M | K9: Frank W
A10: Tailem Bend 3 BESS | B10: BESS | C10: SA | D10: 204 / 408 MWh | F10: S1 | H10: TRUE | I10: TRUE | J10: Wriece M | K10: Jack S
A11: Fosterville Solar Farm and BESS | B11: SF/BESS | C11: VIC | D11: 80 MW SF / 120 MW (240MWh) BESS | F11: V6 | H11: TRUE | I11: TRUE | J11: Wriece M | K11: Frank W
H12: FALSE | I12: FALSE
A14: Baringa Renewable Plant Assumptions Q2 25
A15: Project Name | B15: Tech | C15: Region | D15: Capacity | E15: Commercial Use Date | F15: REZ | H15: Added? | I15: Checked | J15: Responsible | K15: Reviewed by | L15: Comments
A16: Aldoga Solar Farm | B16: Solar | C16: QLD | D16: 380 | E16: 45870 | F16: Q6 | H16: TRUE | I16: TRUE | J16: Frank W | K16: Wriece M | L16: Already modelled - Changed commissioning date
A17: Borumba PHES | B17: Storage - Pumped Hydro | C17: QLD | D17: 1000 | E17: 49126 | H17: TRUE | I17: TRUE | J17: Frank W | K17: Wriece M | L17: Not a committed project based on latest RUGs received in Jul 25.
A18: Borumba PHES | B18: Storage - Pumped Hydro | C18: QLD | D18: 2000 | E18: 49491 | H18: TRUE | I18: TRUE | J18: Frank W | K18: Wriece M | L18: Not a committed project based on latest RUGs received in Jul 25.
A19: Boulder Creek Wind Farm - stage 1 | B19: Wind | C19: QLD | D19: 228 | E19: 46753 | F19: Q6 | H19: TRUE | I19: TRUE | J19: Frank W | K19: Wriece M | L19: Already modelled - Changed commissioning date
A20: Brendale BESS | B20: Storage - Battery | C20: QLD | D20: 205 MW / 410 MWh | E20: 46174 | H20: TRUE | I20: TRUE | J20: Frank W | K20: Wriece M | L20: Already modelled
A21: Broadsound BESS | B21: Storage - Battery | C21: QLD | D21: 180MW / 360MWh | E21: 46388 | F21: Q4 | H21: TRUE | I21: TRUE | J21: Frank W | K21: Wriece M | L21: Not a committed project based on latest RUGs received in Jul 25.
A22: Broadsound Solar Farm | B22: Solar | C22: QLD | D22: 296 | E22: 46388 | F22: Q4 | H22: TRUE | I22: TRUE | J22: Frank W | K22: Wriece M | L22: Already modelled
A23: Bundaberg Solar Farm | B23: Solar | C23: QLD | D23: 78 | E23: 45992 | F23: Q6 | H23: TRUE | I23: TRUE | J23: Frank W | K23: Wriece M | L23: Not a committed project based on latest RUGs received in Jul 25.
A24: Bungama BESS | B24: Storage - Battery | C24: SA | D24: 150 MW / 300 MWh | E24: 46082 | F24: S5 | H24: TRUE | I24: TRUE | J24: Wriece M | K24: Frank W
A25: Calala BESS | B25: Storage - Battery | C25: NSW | D25: 250 MW / 500 MWh | E25: 46296 | F25: N1 | H25: TRUE | I25: TRUE | J25: Jack S | K25: Wriece M | L25: Changed from 300 to 250
A26: Carwarp Energy Park - Solar Farm | B26: Solar | C26: VIC | D26: 171 | E26: 46569 | F26: V2 | H26: TRUE | I26: TRUE | J26: Wriece M | K26: Jack S | L26: Already modelled - Changed commissioning date
A27: Clarke Creek Wind Farm - Stage 1 | B27: Wind | C27: QLD | D27: 450 | E27: 45901 | F27: Q4 | H27: TRUE | I27: TRUE | J27: Frank W | K27: Wriece M | L27: Already modelled - Changed commissioning date
A28: Clements Gap BESS | B28: Storage - Battery | C28: SA | D28: 60 MW / 143 MWh | E28: 46204 | H28: TRUE | I28: TRUE | J28: Wriece M | K28: Frank W | L28: Already modelled
A29: Coppabella Wind Farm | B29: Wind | C29: NSW | D29: 275 | E29: 46935 | F29: N7 | H29: TRUE | I29: TRUE | J29: Jack S | K29: Wriece M
A30: Culcairn Solar Farm | B30: Solar | C30: NSW | D30: 350 | E30: 46023 | F30: N6 | H30: TRUE | I30: TRUE | J30: Jack S | K30: Wriece M | L30: WM - Commissioning date needs to be updated
A31: Dugald River Solar Farm | B31: Solar | C31: QLD | D31: 88 | E31: 48030 | F31: Q2 | H31: TRUE | I31: TRUE | J31: Frank W | K31: Wriece M | L31: Not modelled as it is a remote project at Mount Isa that is connected to main grid.
A32: Eraring Battery | B32: Storage - Battery | C32: NSW | D32: 460 MW / 1770 MWh | E32: 46204 | F32: N3 | H32: TRUE | I32: TRUE | J32: Jack S | K32: Wriece M | L32: Storage 2h -> 4h
A33: Eraring Big Battery - Stage 2 | B33: Storage - Battery | C33: NSW | D33: 240MW / 1030MWh | E33: 46569 | F33: N3 | H33: TRUE | I33: TRUE | J33: Jack S | K33: Wriece M | L33: Added stage 2
A34: Fulham Solar Farm | B34: Solar | C34: VIC | D34: 80 | E34: 46722 | F34: V5 | H34: TRUE | I34: TRUE | J34: Wriece M | K34: Frank W | L34: Already modelled - Changed commissioning date
A35: Fulham Solar Farm - BESS | B35: Storage - Battery | C35: VIC | D35: 64 MW / 128 MWh | E35: 46722 | F35: V5 | H35: TRUE | I35: TRUE | J35: Wriece M | K35: Jack S | L35: Already modelled - Changed commissioning date
A36: Glenellen Solar Farm | B36: Solar | C36: NSW | D36: 260 | E36: 46023 | F36: N6 | H36: TRUE | I36: TRUE | J36: Jack S | K36: Wriece M | L36: COD. Max capacity 200 -> 260.
A37: Golden Plains Wind Farm East | B37: Wind | C37: VIC | D37: 756 | E37: 45870 | F37: V4 | H37: TRUE | I37: TRUE | J37: Wriece M | K37: Frank W | L37: Already modelled - Changed commissioning date
A38: Golden Plains Wind Farm West | B38: Wind | C38: VIC | D38: 577 | E38: 46569 | F38: V4 | H38: TRUE | I38: TRUE | J38: Wriece M | K38: Jack S | L38: Already modelled - Changed commissioning date
A39: Goorambat East Solar Farm | B39: Solar | C39: VIC | D39: 250 | E39: 46388 | F39: V6 | H39: TRUE | I39: TRUE | J39: Wriece M | K39: Frank W | L39: Already modelled - Changed commissioning date
A40: Goulburn River BESS | B40: Storage - Battery | C40: NSW | D40: 49 MW / 392 MWh | E40: 46569 | H40: TRUE | I40: TRUE | J40: Jack S | K40: Wriece M | L40: Added. 8h BESS. PHES profile used.
A41: Goulburn River Solar Farm | B41: Solar | C41: NSW | D41: 450 | E41: 46204 | F41: N3 | H41: TRUE | I41: TRUE | J41: Jack S | K41: Wriece M | L41: COD
A42: Griffith BESS | B42: Storage - Battery | C42: NSW | D42: 100 MW / 800MWh | E42: 46935 | F42: N5 | H42: TRUE | I42: TRUE | J42: Jack S | K42: Wriece M | L42: Added. 8h BESS. PHES profile used.
...

Sheet GLL List
A1: Name | B1: BusNum | C1: GenID | D1: Tech | E1: Portfolio | F1: Phase | G1: Location | H1: DC Capacity | I1: Export Limit | J1: NTP Date | K1: COD | L1: Status | M1: Included in reporting? | N1: GLL Update Req'd? | O1: GLL Received and Checked? | Q1: Added? | R1: Checked | S1: Responsible | T1: Reviewed by
A2: Moah Creek | B2: 80160 | C2: 51 | D2: Solar | E2: JV | F2: 2 | G2: QLD | I2: 285 | J2: 46600 | K2: 47423 | L2: Ok | M2: Included | Q2: FALSE | R2: TRUE | S2: Charlie G | T2: Frank W
A3: Wooderson | B3: 80308 | C3: 50 | D3: Solar | E3: JV | F3: 2 | G3: QLD | I3: 450 | J3: 46784 | K3: 47757 | L3: Ok | M3: Included | Q3: FALSE | R3: TRUE | S3: Charlie G | T3: Frank W
A4: Springdale | D4: Solar | E4: JV | F4: 3 | G4: NSW | I4: 100 | L4: Exclude - direction by Commercial - turn off | M4: Excluded | Q4: TRUE | R4: FALSE | S4: Jack | T4: Wriece
A5: Tallawang | B5: 80142 | C5: 11 | D5: Solar | E5: JV | F5: 3 | G5: NSW | I5: 500 | J5: 46357 | K5: 47453 | L5: Exclude - direction by Commercial - turn off | M5: Excluded | N5: Site is has access rights from ASL, so should leave connected but not report. Baringa confirmed on call that they model CWO as a lumped generator. | Q5: TRUE | R5: FALSE | S5: Jack | T5: Wriece
A6: Argoon | B6: 80031 | C6: 11 | D6: Onshore Wind | E6: RES-Only | F6: 2 | G6: NSW | I6: 612 | J6: 48761 | K6: 49919 | L6: Ok | M6: Included | Q6: FALSE | R6: TRUE | S6: Charlie G | T6: Jack S
A7: Bogandilla | B7: 46760 | C7: 76 | D7: Onshore Wind | E7: RES-Only | F7: 2 | G7: QLD | I7: 578 | J7: 47150 | K7: 48458 | L7: Ok | M7: Included | Q7: FALSE | R7: TRUE | S7: Charlie G | T7: Frank W
A8: Cannie | B8: 80026 | C8: 50 | D8: Onshore Wind | E8: RES-Only | F8: 2 | G8: VIC | I8: 1000.8 | J8: 47331 | K8: 48700 | L8: Ok | M8: Included | Q8: FALSE | R8: TRUE | S8: Charlie G | T8: Wriece M
A9: Kerrs Creek | B9: 80021 | C9: 80 | D9: Onshore Wind | E9: RES-Only | F9: 2 | G9: NSW | I9: 374 | J9: 46692 | K9: 47696 | L9: Ok | M9: Included | Q9: FALSE | R9: TRUE | S9: Charlie G | T9: Jack S
A10: Moah Creek | B10: 80160 | C10: 50 | D10: Onshore Wind | E10: JV | F10: 3 | G10: QLD | I10: 360 | J10: 46143 | K10: 47119 | L10: Ok | M10: Included | Q10: FALSE | R10: TRUE | S10: Charlie G | T10: Frank W
A11: Mount Sugarloaf | B11: 46240 | C11: 50 | D11: Onshore Wind | E11: JV | F11: 2 | G11: QLD | I11: 510 | J11: 47331 | K11: 48549 | L11: Ok | M11: Included | Q11: FALSE | R11: TRUE | S11: Charlie G | T11: Frank W
A12: Silver Eye (Tara) | B12: 46782 | C12: 50 | D12: Onshore Wind | E12: JV | F12: 1 | G12: QLD | I12: 799.2 | J12: 47849 | K12: 49218 | L12: Ok | M12: Included | Q12: FALSE | R12: TRUE | S12: Charlie G | T12: Frank W
A13: Tarong West | B13: 80116 | C13: 80 | D13: Onshore Wind | E13: RES-Only | F13: 3 | G13: QLD | I13: 436.5 | J13: 46174 | K13: 47757 | L13: Ok | M13: Included | Q13: FALSE | R13: TRUE | S13: Charlie G | T13: Frank W
A14: Watta Wella | B14: 32773 | C14: 55 | D14: Onshore Wind | E14: RES-Only | F14: 3 | G14: VIC | I14: 306 | J14: 46661 | K14: 47727 | L14: Ok | M14: Included | Q14: FALSE | R14: TRUE | S14: Charlie G | T14: Wriece M
A15: Gippsland | D15: Offshore Wind | E15: JV | F15: 2 | G15: VIC | I15: 560 | J15: 47484 | K15: 48761 | L15: Exclude - direction by Commercial - turn off | M15: Excluded | Q15: FALSE | R15: FALSE
A16: Goombargana | D16: Onshore Wind | E16: New Sites | F16: 1 | G16: NSW | I16: 1008 | J16: 47939 | K16: 49614 | L16: Include- direction by Commercial | M16: Excluded | N16: This quarter was not run but results from bespoke run were compared to Walla BESS and decision to use Walla BESS results in lieu was decided on | Q16: FALSE | R16: FALSE | S16: Jack | T16: Beau
A17: Bunyip North BESS | D17: Battery Storage | E17: RES-Only | F17: 2 | H17: 400 | J17: 46661 | K17: 47362 | L17: Include for this run - capacity changed to 400MW - direction commercial | Q17: TRUE | R17: TRUE | S17: Wriece M | T17: Beau
A18: Tragowel BESS | D18: Battery Storage | E18: New Sites | F18: 1 | H18: 500 | J18: 47484 | K18: 48092 | L18: Include for this run - direction commercial | Q18: TRUE | R18: TRUE | S18: Wriece M | T18: Beau
A19: Watta Wella BESS | D19: Battery Storage | E19: New Sites | F19: 1 | H19: 500 | J19: 47484 | K19: 48092 | L19: Include for this run - direction by commercial | Q19: TRUE | R19: TRUE | S19: Wriece M | T19: Beau
A20: Walla Walla BESS | D20: Battery Storage | E20: New Sites | F20: 1 | H20: 650 / 2hr | J20: 47119 | K20: 47727 | L20: Include for this run - direction by commercial | Q20: TRUE | R20: TRUE | S20: Jack | T20: Beau/Wriece

Sheet Scenario Checklist
A1: Scenario Checklist
C2: Baringa RC
A3: Augmentations | C3: Q3 2025 | D3: Q4 2025
A4: Name | B4: Region | C4: Date | D4: Date | E4: Complete? | F4: Checked? | H4: Responsible | I4: Reviewed by
A5: Project Energy Connect | B5: NSW-SA | C5: 46569 | D5: 46569 | E5: TRUE | F5: TRUE | H5: Wriece M | I5: Jack S
A6: Western Renewables Link | B6: VIC | C6: 47453 | D6: 47453 | E6: TRUE | F6: TRUE | H6: Wriece M | I6: Beau H
A7: CWO REZ | B7: NSW | C7: 46966 | D7: 47088 | E7: TRUE | F7: TRUE | H7: Wriece M | I7: Jack S
A8: Sydney Ring | B8: NSW | C8: 47088 | D8: 47088 | E8: TRUE | F8: TRUE | H8: Wriece M | I8: Jack S
A9: HumeLink | B9: NSW | C9: 47300 | D9: 47300 | E9: TRUE | F9: TRUE | H9: Wriece M | I9: Jack S
A10: Marinus Link | C10: 47818 | D10: 47818 | E10: TRUE | F10: TRUE | H10: Ignore
A11: New England REZ | B11: NSW | C11: 48396 | D11: 48396 | E11: TRUE | F11: TRUE | H11: Wriece M | I11: Jack S
A12: VNI West | B12: VIC - NSW | C12: 48030 | D12: 48030 | E12: TRUE | F12: TRUE | H12: Wriece M | I12: Beau H
A13: Copperstring East | B13: QLD | C13: 48030 | D13: 48030 | E13: TRUE | F13: TRUE | H13: Wriece M | I13: Frank W
A14: QLD Supergrid South | B14: QLD | C14: Removed | D14: Removed | E14: TRUE | F14: TRUE | H14: Wriece M | I14: Frank W
A15: Borumba Hydro | B15: QLD | C15: 49126 | D15: Cancelled | E15: TRUE | F15: TRUE | H15: Wriece M | I15: Frank W
A16: Snowy 2.0 | B16: NSW | C16: 47453 | D16: 47453 | E16: TRUE | F16: TRUE | H16: Wriece M | I16: Jack S
A17: Copperstring West | B17: QLD | C17: 49126 | D17: 49126 | E17: TRUE | F17: TRUE | H17: Wriece M | I17: Frank W
A18: Ross-Nebo | B18: QLD | C18: 50952 | D18: 50952 | E18: TRUE | F18: TRUE | H18: Wriece M | I18: Frank W
A19: Calvale-Wandoan | B19: QLD | C19: 50952 | D19: 50952 | E19: TRUE | F19: TRUE | H19: Wriece M | I19: Frank W
A20: QLD Supergrid North | B20: QLD | C20: Removed | D20: Removed | E20: TRUE | F20: TRUE | H20: Wriece M | I20: Frank W
A21: QNI Connect | B21: QLD - NSW | C21: 49126 | D21: 49126 | E21: TRUE | F21: TRUE | H21: Wriece M | I21: Frank W
A22: North west strengthening program | B22: VIC | D22: 49491 | E22: TRUE | F22: TRUE | H22: Wriece M | I22: Beau H
A23: South west expansion program | B23: VIC | D23: 48761 | E23: TRUE | F23: TRUE
E24: FALSE | F24: FALSE
C26: Baringa RC
A27: Coal Plant Closures | C27: Q3 2025 | D27: Q4 2025
A28: Name | B28: Region | C28: Date | D28: Date (FY) | E28: Complete? | F28: Checked? | H28: Responsible | I28: Reviewed by | U28: Key for dates retirement Baringa assumption - we assume mid way through year ie 1/7 which does not contravene the below footnote
A29: Liddell | B29: NSW | C29: 2022-2023 | D29: 2022-2023 | E29: TRUE | F29: TRUE | H29: Wriece M | I29: Beau H
A30: Eraring | B30: NSW | C30: 2028-2029 | D30: 2028-2029 | E30: TRUE | F30: TRUE | H30: Wriece M | I30: Beau H
A31: Vales Point B | B31: NSW | C31: 2032 | D31: 2031 | E31: TRUE | F31: TRUE | H31: Wriece M | I31: Beau H
A32: Bayswater | B32: NSW | C32: 2033-2034 | D32: 2033-2034 | E32: TRUE | F32: TRUE | H32: Wriece M | I32: Beau H
A33: Mount Piper | B33: NSW | C33: 2040 | D33: 2039 | E33: TRUE | F33: TRUE | H33: Wriece M | I33: Beau H
A34: Gladstone | B34: QLD | C34: 2029 | D34: 2029 | E34: TRUE | F34: TRUE | H34: Wriece M | I34: Frank W
A35: Callide B | B35: QLD | C35: 2032 | D35: 2032 | E35: TRUE | F35: TRUE | H35: Wriece M | I35: Frank W
A36: Tarong | B36: QLD | C36: 2034 | D36: 2034 | E36: TRUE | F36: TRUE | H36: Wriece M | I36: Frank W
A37: Tarong North | B37: QLD | C37: 2038 | D37: 2038 | E37: TRUE | F37: TRUE | H37: Wriece M | I37: Frank W
A38: Kogan Creek | B38: QLD | C38: 2043 | D38: 2043 | E38: TRUE | F38: TRUE | H38: Wriece M | I38: Frank W
A39: Callide C | B39: QLD | C39: 2040-2041 | D39: 2040-2041 | E39: TRUE | F39: TRUE | H39: Wriece M | I39: Frank W
A40: Stanwell | B40: QLD | C40: 2035-2036 | D40: 2035-2036 | E40: TRUE | F40: TRUE | H40: Wriece M | I40: Frank W
... A44: Loy Yang B | B44: VIC | C44: 2037-2038 | D44: 2037-2038 | E44: TRUE | F44: TRUE | H44: Wriece M | I44: Beau H
...

Sheet RUG compare
A1: 20250714 Download - https://reshive.sharepoint.com/:f:/r/sites/Hive_1556/Shared%20Documents/01%20Knowledge%20Base/07%20AEMO%20Snapshots%20and%20RUGs?csf=1&web=1&e=FdNpmd | J1: 20250317 in 1_For_current_studies
A2: NSW | C2: VIC | E2: SA | G2: QLD | J2: NSW | K2: VIC | L2: SA | M2: QLD
A3: Appin Power Station | B3: =IF(ISNA(VLOOKUP(A3,J:J,1,FALSE)),"Add Gen","Modelled prev") -> Modelled prev | C3: Axedale Solar Farm & BESS | D3: =IF(ISNA(VLOOKUP(C3,K:K,1,FALSE)),"Add Gen","Modelled prev") -> Modelled prev | E3: Adelaide Desalination Plant | F3: =IF(ISNA(VLOOKUP(E3,L:L,1,FALSE)),"Add Gen","Modelled prev") -> Modelled prev | G3: Aldoga Solar Farm | H3: =IF(ISNA(VLOOKUP(G3,M:M,1,FALSE)),"Add Gen","Modelled prev") -> Modelled prev | J3: Appin Power Station | K3: Axedale Solar Farm & BESS | L3: Adelaide Desalination Plant | M3: Aldoga Solar Farm
A4: Argyle Solar Farm | B4: =IF(ISNA(VLOOKUP(A4,J:J,1,FALSE)),"Add Gen","Modelled prev") -> Modelled prev | C4: Ballarat Battery Energy Storage System | D4: =IF(ISNA(VLOOKUP(C4,K:K,1,FALSE)),"Add Gen","Modelled prev") -> Modelled prev | E4: Barker Inlet Power Station | F4: =IF(ISNA(VLOOKUP(E4,L:L,1,FALSE)),"Add Gen","Modelled prev") -> Modelled prev | G4: Alligator Creek SVC | H4: =IF(ISNA(VLOOKUP(G4,M:M,1,FALSE)),"Add Gen","Modelled prev") -> Modelled prev | J4: Argyle Solar Farm | K4: Ballarat Battery Energy Storage System | L4: Barker Inlet Power Station | M4: Alligator Creek SVC
A5: Avonlie Solar Farm | B5: =IF(ISNA(VLOOKUP(A5,J:J,1,FALSE)),"Add Gen","Modelled prev") -> Modelled prev | C5: Bannerton Solar Farm | D5: =IF(ISNA(VLOOKUP(C5,K:K,1,FALSE)),"Add Gen","Modelled prev") -> Modelled prev | E5: Blyth BESS | F5: =IF(ISNA(VLOOKUP(E5,L:L,1,FALSE)),"Add Gen","Modelled prev") -> Modelled prev | G5: Aramara Solar Farm | H5: =IF(ISNA(VLOOKUP(G5,M:M,1,FALSE)),"Add Gen","Modelled prev") -> Modelled prev | J5: Avonlie Solar Farm | K5: Bannerton Solar Farm | L5: Blyth BESS | M5: Aramara Solar Farm
A6: Bango 973 Wind Farm | B6: =IF(ISNA(VLOOKUP(A6,J:J,1,FALSE)),"Add Gen","Modelled prev") -> Modelled prev | C6: Berrybank 2 Wind Farm | D6: =IF(ISNA(VLOOKUP(C6,K:K,1,FALSE)),"Add Gen","Modelled prev") -> Modelled prev | E6: Bolivar Power Station | F6: =IF(ISNA(VLOOKUP(E6,L:L,1,FALSE)),"Add Gen","Modelled prev") -> Modelled prev | G6: Baking Board Solar Farm | H6: =IF(ISNA(VLOOKUP(G6,M:M,1,FALSE)),"Add Gen","Modelled prev") -> Modelled prev | J6: Bango 973 Wind Farm | K6: Berrybank 2 Wind Farm | L6: Bolivar Power Station | M6: Baking Board Solar Farm
A7: Bango 999 Wind Farm | B7: =IF(ISNA(VLOOKUP(A7,J:J,1,FALSE)),"Add Gen","Modelled prev") -> Modelled prev | C7: Bulgana Green Power Hub | D7: =IF(ISNA(VLOOKUP(C7,K:K,1,FALSE)),"Add Gen","Modelled prev") -> Modelled prev | E7: Bolivar Waste Water Treatment Plant | F7: =IF(ISNA(VLOOKUP(E7,L:L,1,FALSE)),"Add Gen","Modelled prev") -> Modelled prev | G7: Banksia Solar Farm | H7: =IF(ISNA(VLOOKUP(G7,M:M,1,FALSE)),"Add Gen","Modelled prev") -> Modelled prev | J7: Bango 999 Wind Farm | K7: Bulgana Green Power Hub | L7: Bolivar Waste Water Treatment Plant | M7: Banksia Solar Farm
A8: Bayswater Power Station Unit 1 | B8: =IF(ISNA(VLOOKUP(A8,J:J,1,FALSE)),"Add Gen","Modelled prev") -> Modelled prev | C8: Carag Solar Farm | D8: =IF(ISNA(VLOOKUP(C8,K:K,1,FALSE)),"Add Gen","Modelled prev") -> Modelled prev | E8: Bungala One Solar Farm | F8: =IF(ISNA(VLOOKUP(E8,L:L,1,FALSE)),"Add Gen","Modelled prev") -> Modelled prev | G8: Barcaldine Solar Farm | H8: =IF(ISNA(VLOOKUP(G8,M:M,1,FALSE)),"Add Gen","Modelled prev") -> Modelled prev | J8: Bayswater Power Station Unit 1 | K8: Carag Solar Farm | L8: Bungala One Solar Farm | M8: Barcaldine Solar Farm
A9: Bayswater Power Station Unit 2 | B9: =IF(ISNA(VLOOKUP(A9,J:J,1,FALSE)),"Add Gen","Modelled prev") -> Modelled prev | C9: Carisbrook Solar Farm | D9: =IF(ISNA(VLOOKUP(C9,K:K,1,FALSE)),"Add Gen","Modelled prev") -> Modelled prev | E9: Bungala Two Solar Farm | F9: =IF(ISNA(VLOOKUP(E9,L:L,1,FALSE)),"Add Gen","Modelled prev") -> Modelled prev | G9: Blackwater Gregory Dysart Moranbah MtMclaren SVCs | H9: =IF(ISNA(VLOOKUP(G9,M:M,1,FALSE)),"Add Gen","Modelled prev") -> Modelled prev | J9: Bayswater Power Station Unit 2 | K9: Carisbrook Solar Farm | L9: Bungala Two Solar Farm | M9: Blackwater Gregory Dysart Moranbah MtMclaren SVCs
A10: Bayswater Power Station Unit 3 | B10: =IF(ISNA(VLOOKUP(A10,J:J,1,FALSE)),"Add Gen","Modelled prev") -> Modelled prev | C10: Carwarp Solar Farm Canadian Solar | D10: =IF(ISNA(VLOOKUP(C10,K:K,1,FALSE)),"Add Gen","Modelled prev") -> Modelled prev | E10: Bungama Battery Energy Storage System (AMP) | F10: =IF(ISNA(VLOOKUP(E10,L:L,1,FALSE)),"Add Gen","Modelled prev") -> Modelled prev | G10: Bluegrass Solar Farm | H10: =IF(ISNA(VLOOKUP(G10,M:M,1,FALSE)),"Add Gen","Modelled prev") -> Modelled prev | J10: Bayswater Power Station Unit 3 | K10: Carwarp Solar Farm Canadian Solar | L10: Bungama Battery Energy Storage System (AMP) | M10: Bluegrass Solar Farm
A11: Bayswater Power Station Unit 4 | B11: =IF(ISNA(VLOOKUP(A11,J:J,1,FALSE)),"Add Gen","Modelled prev") -> Modelled prev | C11: Challicum Hills Wind Farm | D11: =IF(ISNA(VLOOKUP(C11,K:K,1,FALSE)),"Add Gen","Modelled prev") -> Modelled prev | E11: Christies Beach WWTP | F11: =IF(ISNA(VLOOKUP(E11,L:L,1,FALSE)),"Add Gen","Modelled prev") -> Modelled prev | G11: Boulder Creek Wind Farm | H11: =IF(ISNA(VLOOKUP(G11,M:M,1,FALSE)),"Add Gen","Modelled prev") -> Modelled prev | J11: Bayswater Power Station Unit 4 | K11: Challicum Hills Wind Farm | L11: Christies Beach WWTP | M11: Boulder Creek Wind Farm
A12: Beryl Solar Farm | B12: =IF(ISNA(VLOOKUP(A12,J:J,1,FALSE)),"Add Gen","Modelled prev") -> Modelled prev | C12: Codrington Wind Farm | D12: =IF(ISNA(VLOOKUP(C12,K:K,1,FALSE)),"Add Gen","Modelled prev") -> Modelled prev | E12: Clements Gap BESS | F12: =IF(ISNA(VLOOKUP(E12,L:L,1,FALSE)),"Add Gen","Modelled prev") -> Modelled prev | G12: Bouldercombe Battery Project | H12: =IF(ISNA(VLOOKUP(G12,M:M,1,FALSE)),"Add Gen","Modelled prev") -> Modelled prev | J12: Beryl Solar Farm | K12: Codrington Wind Farm | L12: Clements Gap BESS | M12: Bouldercombe Battery Project
A13: Biala Wind Farm | B13: =IF(ISNA(VLOOKUP(A13,J:J,1,FALSE)),"Add Gen","Modelled prev") -> Modelled prev | C13: Cohuna Solar Farm | D13: =IF(ISNA(VLOOKUP(C13,K:K,1,FALSE)),"Add Gen","Modelled prev") -> Modelled prev | E13: Clements Gap WF | F13: =IF(ISNA(VLOOKUP(E13,L:L,1,FALSE)),"Add Gen","Modelled prev") -> Modelled prev | G13: Braemar 1 Power Station | H13: =IF(ISNA(VLOOKUP(G13,M:M,1,FALSE)),"Add Gen","Modelled prev") -> Modelled prev | J13: Biala Wind Farm | K13: Cohuna Solar Farm | L13: Clements Gap WF | M13: Braemar 1 Power Station
A14: Bodangora Wind Farm | B14: =IF(ISNA(VLOOKUP(A14,J:J,1,FALSE)),"Add Gen","Modelled prev") -> Modelled prev | C14: Coonooer Bridge Wind Farm | D14: =IF(ISNA(VLOOKUP(C14,K:K,1,FALSE)),"Add Gen","Modelled prev") -> Modelled prev | E14: Dalrymple Battery Energy Storage System | F14: =IF(ISNA(VLOOKUP(E14,L:L,1,FALSE)),"Add Gen","Modelled prev") -> Modelled prev | G14: Braemar 2 Power Station | H14: =IF(ISNA(VLOOKUP(G14,M:M,1,FALSE)),"Add Gen","Modelled prev") -> Modelled prev | J14: Bodangora Wind Farm | K14: Coonooer Bridge Wind Farm | L14: Dalrymple Battery Energy Storage System | M14: Braemar 2 Power Station
... A59: Metz Solar Farm | B59: =IF(ISNA(VLOOKUP(A59,J:J,1,FALSE)),"Add Gen","Modelled prev") -> Modelled prev | C59: Rangebank Battery Energy Storage System | D59: =IF(ISNA(VLOOKUP(C59,K:K,1,FALSE)),"Add Gen","Modelled prev") -> Modelled prev | E59: Torrens Island BESS | F59: =IF(ISNA(VLOOKUP(E59,L:L,1,FALSE)),"Add Gen","Modelled prev") -> Modelled prev | G59: Punchs Creek Solar Farm | H59: =IF(ISNA(VLOOKUP(G59,M:M,1,FALSE)),"Add Gen","Modelled prev") -> Modelled prev | J59: Molong Solar Farm | K59: Salt Creek Wind Farm | L59: Willogoleche WF | M59: Roma Gas Turbine Station
A60: Molong Solar Farm | B60: =IF(ISNA(VLOOKUP(A60,J:J,1,FALSE)),"Add Gen","Modelled prev") -> Modelled prev | C60: Ryan Corner Wind Farm | D60: =IF(ISNA(VLOOKUP(C60,K:K,1,FALSE)),"Add Gen","Modelled prev") -> Modelled prev | E60: Willogoleche WF | F60: =IF(ISNA(VLOOKUP(E60,L:L,1,FALSE)),"Add Gen","Modelled prev") -> Modelled prev | G60: Roma Gas Turbine Station | H60: =IF(ISNA(VLOOKUP(G60,M:M,1,FALSE)),"Add Gen","Modelled prev") -> Modelled prev | J60: Molongo BESS | K60: Stockyard Hill Wind Farm | M60: Ross River Solar Farm
A61: Molongo BESS | B61: =IF(ISNA(VLOOKUP(A61,J:J,1,FALSE)),"Add Gen","Modelled prev") -> Modelled prev | C61: Salt Creek Wind Farm | D61: =IF(ISNA(VLOOKUP(C61,K:K,1,FALSE)),"Add Gen","Modelled prev") -> Modelled prev | G61: Ross River Solar Farm | H61: =IF(ISNA(VLOOKUP(G61,M:M,1,FALSE)),"Add Gen","Modelled prev") -> Modelled prev | J61: Mount Piper Power Station | K61: Terang BESS | M61: Ross SVC
A62: Mount Piper Power Station | B62: =IF(ISNA(VLOOKUP(A62,J:J,1,FALSE)),"Add Gen","Modelled prev") -> Modelled prev | C62: Stockyard Hill Wind Farm | D62: =IF(ISNA(VLOOKUP(C62,K:K,1,FALSE)),"Add Gen","Modelled prev") -> Modelled prev | G62: Ross SVC | H62: =IF(ISNA(VLOOKUP(G62,M:M,1,FALSE)),"Add Gen","Modelled prev") -> Modelled prev | J62: Mugga Lane Solar Park | K62: Victorian Big Battery | M62: Strathmore SVC
A63: Mugga Lane Solar Park | B63: =IF(ISNA(VLOOKUP(A63,J:J,1,FALSE)),"Add Gen","Modelled prev") -> Modelled prev | C63: Terang BESS | D63: =IF(ISNA(VLOOKUP(C63,K:K,1,FALSE)),"Add Gen","Modelled prev") -> Modelled prev | G63: Strathmore SVC | H63: =IF(ISNA(VLOOKUP(G63,M:M,1,FALSE)),"Add Gen","Modelled prev") -> Modelled prev | J63: Mulwala Solar Farm | K63: Wangaratta Solar Farm | M63: Sunshine Coast Solar Farm
A64: Mulwala Solar Farm | B64: =IF(ISNA(VLOOKUP(A64,J:J,1,FALSE)),"Add Gen","Modelled prev") -> Modelled prev | C64: Victorian Big Battery | D64: =IF(ISNA(VLOOKUP(C64,K:K,1,FALSE)),"Add Gen","Modelled prev") -> Modelled prev | G64: Sunshine Coast Solar Farm | H64: =IF(ISNA(VLOOKUP(G64,M:M,1,FALSE)),"Add Gen","Modelled prev") -> Modelled prev | J64: Murray 2 Power Station | K64: Winton Solar Farm | M64: Supernode BESS
A65: Murray 2 Power Station | B65: =IF(ISNA(VLOOKUP(A65,J:J,1,FALSE)),"Add Gen","Modelled prev") -> Modelled prev | C65: Wangaratta Solar Farm | D65: =IF(ISNA(VLOOKUP(C65,K:K,1,FALSE)),"Add Gen","Modelled prev") -> Modelled prev | G65: Supernode BESS | H65: =IF(ISNA(VLOOKUP(G65,M:M,1,FALSE)),"Add Gen","Modelled prev") -> Modelled prev | J65: Muswellbrook SF | K65: Woolsthorpe Wind Farm | M65: Swanbank E Power Station
A66: Muswellbrook SF | B66: =IF(ISNA(VLOOKUP(A66,J:J,1,FALSE)),"Add Gen","Modelled prev") -> Modelled prev | C66: Woolsthorpe Wind Farm | D66: =IF(ISNA(VLOOKUP(C66,K:K,1,FALSE)),"Add Gen","Modelled prev") -> Modelled prev | G66: Swanbank BESS | H66: =IF(ISNA(VLOOKUP(G66,M:M,1,FALSE)),"Add Gen","Modelled prev") -> Add Gen | J66: Narromine Solar Farm | K66: Wooreen BESS | M66: Tableland Sugar Mill Green Energy Power Station
A67: Narromine Solar Farm | B67: =IF(ISNA(VLOOKUP(A67,J:J,1,FALSE)),"Add Gen","Modelled prev") -> Modelled prev | C67: Wooreen BESS | D67: =IF(ISNA(VLOOKUP(C67,K:K,1,FALSE)),"Add Gen","Modelled prev") -> Modelled prev | G67: Swanbank E Power Station | H67: =IF(ISNA(VLOOKUP(G67,M:M,1,FALSE)),"Add Gen","Modelled prev") -> Modelled prev | J67: Nevertire Solar Farm | K67: Wunghnu Solar Farm | M67: Tarong BESS
A68: Nevertire Solar Farm | B68: =IF(ISNA(VLOOKUP(A68,J:J,1,FALSE)),"Add Gen","Modelled prev") -> Modelled prev | C68: Wunghnu Solar Farm | D68: =IF(ISNA(VLOOKUP(C68,K:K,1,FALSE)),"Add Gen","Modelled prev") -> Modelled prev | G68: Tableland Sugar Mill Green Energy Power Station | H68: =IF(ISNA(VLOOKUP(G68,M:M,1,FALSE)),"Add Gen","Modelled prev") -> Modelled prev | J68: New England Battery Energy Storage System | K68: Yaloak South Wind Farm | M68: Tully Sugar Mill
A69: New England Battery Energy Storage System | B69: =IF(ISNA(VLOOKUP(A69,J:J,1,FALSE)),"Add Gen","Modelled prev") -> Modelled prev | C69: Yaloak South Wind Farm | D69: =IF(ISNA(VLOOKUP(C69,K:K,1,FALSE)),"Add Gen","Modelled prev") -> Modelled prev | G69: Tarong BESS | H69: =IF(ISNA(VLOOKUP(G69,M:M,1,FALSE)),"Add Gen","Modelled prev") -> Modelled prev | J69: New England Solar Farm | K69: Yatpool Solar Farm | M69: Ulinda Park BESS
A70: New England Solar Farm | B70: =IF(ISNA(VLOOKUP(A70,J:J,1,FALSE)),"Add Gen","Modelled prev") -> Modelled prev | C70: Yatpool Solar Farm | D70: =IF(ISNA(VLOOKUP(C70,K:K,1,FALSE)),"Add Gen","Modelled prev") -> Modelled prev | G70: Tully Sugar Mill | H70: =IF(ISNA(VLOOKUP(G70,M:M,1,FALSE)),"Add Gen","Modelled prev") -> Modelled prev | J70: Nyngan Solar Plant | K70: Yendon Wind Farm | M70: Wambo 2 Wind Farm
A71: Nyngan Solar Plant | B71: =IF(ISNA(VLOOKUP(A71,J:J,1,FALSE)),"Add Gen","Modelled prev") -> Modelled prev | C71: Yendon Wind Farm | D71: =IF(ISNA(VLOOKUP(C71,K:K,1,FALSE)),"Add Gen","Modelled prev") -> Modelled prev | G71: Ulinda Park BESS | H71: =IF(ISNA(VLOOKUP(G71,M:M,1,FALSE)),"Add Gen","Modelled prev") -> Modelled prev | J71: Nyngan substation DVAR | M71: Wambo Wind Farm
A72: Nyngan substation DVAR | B72: =IF(ISNA(VLOOKUP(A72,J:J,1,FALSE)),"Add Gen","Modelled prev") -> Modelled prev | G72: Wambo 2 Wind Farm | H72: =IF(ISNA(VLOOKUP(G72,M:M,1,FALSE)),"Add Gen","Modelled prev") -> Modelled prev | J72: Orana BESS | M72: Wandoan Battery Energy Storage System
A73: Orana BESS | B73: =IF(ISNA(VLOOKUP(A73,J:J,1,FALSE)),"Add Gen","Modelled prev") -> Modelled prev | G73: Wambo Wind Farm | H73: =IF(ISNA(VLOOKUP(G73,M:M,1,FALSE)),"Add Gen","Modelled prev") -> Modelled prev | J73: Queanbeyan Battery Energy Storage System | M73: Wandoan Solar Farm 1
A74: Queanbeyan Battery Energy Storage System | B74: =IF(ISNA(VLOOKUP(A74,J:J,1,FALSE)),"Add Gen","Modelled prev") -> Modelled prev | G74: Wandoan Battery Energy Storage System | H74: =IF(ISNA(VLOOKUP(G74,M:M,1,FALSE)),"Add Gen","Modelled prev") -> Modelled prev | J74: Quorn Park Solar Farm | M74: Warwick Solar Farm 1
A75: Quorn Park Solar Farm | B75: =IF(ISNA(VLOOKUP(A75,J:J,1,FALSE)),"Add Gen","Modelled prev") -> Modelled prev | G75: Wandoan Solar Farm 1 | H75: =IF(ISNA(VLOOKUP(G75,M:M,1,FALSE)),"Add Gen","Modelled prev") -> Modelled prev | J75: Ridgey Creek BESS | M75: Warwick Solar Farm 2
A76: Ridgey Creek BESS | B76: =IF(ISNA(VLOOKUP(A76,J:J,1,FALSE)),"Add Gen","Modelled prev") -> Modelled prev | G76: Warwick Solar Farm 1 | H76: =IF(ISNA(VLOOKUP(G76,M:M,1,FALSE)),"Add Gen","Modelled prev") -> Modelled prev | J76: Riverina Battery Energy Storage System | M76: Western Downs BESS
A77: Riverina Battery Energy Storage System | B77: =IF(ISNA(VLOOKUP(A77,J:J,1,FALSE)),"Add Gen","Modelled prev") -> Modelled prev | G77: Warwick Solar Farm 2 | H77: =IF(ISNA(VLOOKUP(G77,M:M,1,FALSE)),"Add Gen","Modelled prev") -> Modelled prev | J77: Riverina Solar Farm | M77: Western Downs Green Power Hub
A78: Riverina Solar Farm | B78: =IF(ISNA(VLOOKUP(A78,J:J,1,FALSE)),"Add Gen","Modelled prev") -> Modelled prev | G78: Western Downs BESS | H78: =IF(ISNA(VLOOKUP(G78,M:M,1,FALSE)),"Add Gen","Modelled prev") -> Modelled prev | J78: Royalla 1 Solar pv Farm | M78: Woolooga BESS
A79: Royalla 1 Solar pv Farm | B79: =IF(ISNA(VLOOKUP(A79,J:J,1,FALSE)),"Add Gen","Modelled prev") -> Modelled prev | G79: Western Downs Green Power Hub | H79: =IF(ISNA(VLOOKUP(G79,M:M,1,FALSE)),"Add Gen","Modelled prev") -> Modelled prev | J79: Rye Park Wind Farm | M79: Woolooga Solar Farm
A80: Rye Park Wind Farm | B80: =IF(ISNA(VLOOKUP(A80,J:J,1,FALSE)),"Add Gen","Modelled prev") -> Modelled prev | G80: Woolooga BESS | H80: =IF(ISNA(VLOOKUP(G80,M:M,1,FALSE)),"Add Gen","Modelled prev") -> Modelled prev | J80: Sapphire Hybrid Renewable Plant | M80: Woree Static Var Compensator
A81: Sapphire Hybrid Renewable Plant | B81: =IF(ISNA(VLOOKUP(A81,J:J,1,FALSE)),"Add Gen","Modelled prev") -> Modelled prev | G81: Woolooga Solar Farm | H81: =IF(ISNA(VLOOKUP(G81,M:M,1,FALSE)),"Add Gen","Modelled prev") -> Modelled prev | J81: Sebastopol Solar Farm | M81: Yarranlea Solar Farm
A82: Sebastopol Solar Farm | B82: =IF(ISNA(VLOOKUP(A82,J:J,1,FALSE)),"Add Gen","Modelled prev") -> Modelled prev | G82: Woree Static Var Compensator | H82: =IF(ISNA(VLOOKUP(G82,M:M,1,FALSE)),"Add Gen","Modelled prev") -> Modelled prev | J82: SmartWires
A83: SmartWires | B83: =IF(ISNA(VLOOKUP(A83,J:J,1,FALSE)),"Add Gen","Modelled prev") -> Modelled prev | G83: Yarranlea Solar Farm | H83: =IF(ISNA(VLOOKUP(G83,M:M,1,FALSE)),"Add Gen","Modelled prev") -> Modelled prev | J83: Smithfield BESS
A84: Smithfield BESS | B84: =IF(ISNA(VLOOKUP(A84,J:J,1,FALSE)),"Add Gen","Modelled prev") -> Modelled prev | J84: Smithfield Energy Facility
...

Sheet Baringa RC Buildouts Q425
A1: Demand growth
A2: Annual demand on a sent-out basis* | F2: 2026 | G2: 2027 | H2: 2028 | I2: 2029 | J2: 2030 | K2: 2031 | L2: 2032 | M2: 2033 | N2: 2034 | O2: 2035 | P2: 2036 | Q2: 2037 | R2: 2038 | S2: 2039 | T2: 2040 | U2: 2041 | V2: 2042 | W2: 2043 | X2: 2044 | Y2: 2045 | Z2: 2046 | AA2: 2047 | AB2: 2048 | AC2: 2049 | AD2: 2050 | AE2: 2051 | AF2: 2052 | AG2: 2053 | AH2: 2054 | AI2: 2055 | AJ2: 2056 | AK2: 2057 | AL2: 2058 | AM2: 2059 | AN2: 2060
A3: NSW | B3: GWh | F3: 76811 | G3: 78041 | H3: 79914 | I3: 81927 | J3: 84270 | K3: 87269 | L3: 90762 | M3: 93565 | N3: 96351 | O3: 99156 | P3: 102482 | Q3: 105896 | R3: 109360 | S3: 112419 | T3: 115299 | U3: 117938 | V3: 120547 | W3: 123037 | X3: 125440 | Y3: 127791 | Z3: 130229 | AA3: 132576 | AB3: 134934 | AC3: 137035 | AD3: 138900 | AE3: 141170 | AF3: 143655 | AG3: 145569 | AH3: 147390 | AI3: 149426 | AJ3: 151161 | AK3: 152632 | AL3: 153870 | AM3: 154971 | AN3: 155962
A4: QLD | B4: GWh | F4: 62822 | G4: 63855 | H4: 64969 | I4: 66245 | J4: 68221 | K4: 71296 | L4: 75174 | M4: 78490 | N4: 81275 | O4: 86043 | P4: 89356 | Q4: 92488 | R4: 95425 | S4: 98053 | T4: 100565 | U4: 102848 | V4: 105205 | W4: 107633 | X4: 109973 | Y4: 111981 | Z4: 113897 | AA4: 115729 | AB4: 117499 | AC4: 119097 | AD4: 120431 | AE4: 121487 | AF4: 122645 | AG4: 123635 | AH4: 124831 | AI4: 126238 | AJ4: 127317 | AK4: 128194 | AL4: 129007 | AM4: 129720 | AN4: 130499
A5: SA | B5: GWh | F5: 15845 | G5: 16232 | H5: 16536 | I5: 16850 | J5: 20032 | K5: 20460 | L5: 20948 | M5: 21889 | N5: 23009 | O5: 23497 | P5: 24039 | Q5: 24608 | R5: 25165 | S5: 25749 | T5: 26322 | U5: 26951 | V5: 27584 | W5: 28218 | X5: 28877 | Y5: 29504 | Z5: 30160 | AA5: 30793 | AB5: 31446 | AC5: 32039 | AD5: 32597 | AE5: 33077 | AF5: 33555 | AG5: 33980 | AH5: 34393 | AI5: 34881 | AJ5: 35278 | AK5: 35643 | AL5: 35981 | AM5: 36287 | AN5: 36571
A6: TAS | B6: GWh | F6: 11271 | G6: 11502 | H6: 11681 | I6: 11869 | J6: 12083 | K6: 12330 | L6: 12563 | M6: 12963 | N6: 13228 | O6: 13476 | P6: 13722 | Q6: 14005 | R6: 14265 | S6: 14524 | T6: 14727 | U6: 14908 | V6: 15058 | W6: 15172 | X6: 15298 | Y6: 15447 | Z6: 15597 | AA6: 15733 | AB6: 15878 | AC6: 15996 | AD6: 16083 | AE6: 16125 | AF6: 16189 | AG6: 16247 | AH6: 16321 | AI6: 16439 | AJ6: 16459 | AK6: 16491 | AL6: 16510 | AM6: 16539 | AN6: 16580
A7: VIC | B7: GWh | F7: 49600 | G7: 50762 | H7: 51848 | I7: 52868 | J7: 54591 | K7: 57472 | L7: 60175 | M7: 62434 | N7: 64346 | O7: 66564 | P7: 69079 | Q7: 71945 | R7: 74748 | S7: 77233 | T7: 79518 | U7: 81592 | V7: 83786 | W7: 85968 | X7: 88112 | Y7: 90041 | Z7: 92337 | AA7: 94253 | AB7: 96088 | AC7: 97731 | AD7: 99208 | AE7: 100493 | AF7: 101921 | AG7: 103110 | AH7: 104446 | AI7: 105931 | AJ7: 107067 | AK7: 108100 | AL7: 108934 | AM7: 109744 | AN7: 110482
A9: Capacity Mix at FY-end | C9: 2026 | D9: 2027 | E9: 2028 | F9: 2029 | G9: 2030 | H9: 2031 | I9: 2032 | J9: 2033 | K9: 2034 | L9: 2035 | M9: 2036 | N9: 2037 | O9: 2038 | P9: 2039 | Q9: 2040 | R9: 2041 | S9: 2042 | T9: 2043 | U9: 2044 | V9: 2045 | W9: 2046 | X9: 2047 | Y9: 2048 | Z9: 2049 | AA9: 2050 | AB9: 2051 | AC9: 2052 | AD9: 2053 | AE9: 2054 | AF9: 2055 | AG9: 2056 | AH9: 2057 | AI9: 2058 | AJ9: 2059 | AK9: 2060
A10: NSW
A11: Coal | B11: MW | C11: 8260 | D11: 8260 | E11: 6820 | F11: 5380 | G11: 5380 | H11: 5380 | I11: 4060 | J11: 2700 | K11: 1340 | L11: 1340 | M11: 1340 | N11: 1340 | O11: 1340 | P11: 1340 | Q11: 0 | R11: 0 | S11: 0 | T11: 0 | U11: 0 | V11: 0 | W11: 0 | X11: 0 | Y11: 0 | Z11: 0 | AA11: 0 | AB11: 0 | AC11: 0 | AD11: 0 | AE11: 0 | AF11: 0 | AG11: 0 | AH11: 0 | AI11: 0 | AJ11: 0 | AK11: 0
A12: Hydro | B12: MW | C12: 1693 | D12: 1693 | E12: 1693 | F12: 1693 | G12: 1693 | H12: 1693 | I12: 1693 | J12: 1693 | K12: 1693 | L12: 1693 | M12: 1693 | N12: 1693 | O12: 1693 | P12: 1693 | Q12: 1693 | R12: 1693 | S12: 1693 | T12: 1693 | U12: 1693 | V12: 1693 | W12: 1693 | X12: 1693 | Y12: 1693 | Z12: 1693 | AA12: 1693 | AB12: 1693 | AC12: 1693 | AD12: 1693 | AE12: 1693 | AF12: 1693 | AG12: 1693 | AH12: 1693 | AI12: 1693 | AJ12: 1693 | AK12: 1693
A13: Gas | B13: MW | C13: 3076 | D13: 3076 | E13: 3076 | F13: 3076 | G13: 3076 | H13: 3076 | I13: 3076 | J13: 3076 | K13: 3076 | L13: 3076 | M13: 3476 | N13: 3476 | O13: 3476 | P13: 3476 | Q13: 3776 | R13: 3776 | S13: 3776 | T13: 4776 | U13: 4936 | V13: 4694 | W13: 5094 | X13: 5094 | Y13: 5194 | Z13: 5634 | AA13: 6034 | AB13: 6434 | AC13: 5634 | AD13: 5834 | AE13: 5834 | AF13: 6034 | AG13: 6034 | AH13: 6034 | AI13: 6034 | AJ13: 6034 | AK13: 6034
A14: Liquid Fuel | B14: MW | C14: 44 | D14: 44 | E14: 44 | F14: 44 | G14: 44 | H14: 44 | I14: 44 | J14: 44 | K14: 44 | L14: 44 | M14: 0 | N14: 0 | O14: 0 | P14: 0 | Q14: 0 | R14: 0 | S14: 0 | T14: 0 | U14: 0 | V14: 0 | W14: 0 | X14: 0 | Y14: 0 | Z14: 0 | AA14: 0 | AB14: 0 | AC14: 0 | AD14: 0 | AE14: 0 | AF14: 0 | AG14: 0 | AH14: 0 | AI14: 0 | AJ14: 0 | AK14: 0
A15: Wind | B15: MW | C15: 2821 | D15: 2821 | E15: 2821 | F15: 4231 | G15: 5298 | H15: 6514 | I15: 7985 | J15: 10499 | K15: 11311 | L15: 12254 | M15: 13184 | N15: 13684 | O15: 14764 | P15: 15484 | Q15: 17084 | R15: 17234 | S15: 17894 | T15: 17894 | U15: 18214 | V15: 18924 | W15: 19624 | X15: 20396 | Y15: 20466 | Z15: 21216 | AA15: 21836 | AB15: 22346 | AC15: 22346 | AD15: 22536 | AE15: 22586 | AF15: 23036 | AG15: 23286 | AH15: 23286 | AI15: 23506 | AJ15: 23526 | AK15: 24146
A16: Solar | B16: MW | C16: 5743 | D16: 7019 | E16: 7460 | F16: 8054 | G16: 8851 | H16: 9450 | I16: 10098 | J16: 10213 | K16: 10340 | L16: 10480 | M16: 10664 | N16: 10762 | O16: 10861 | P16: 11316 | Q16: 13012 | R16: 13136 | S16: 13838 | T16: 14139 | U16: 14334 | V16: 14709 | W16: 14899 | X16: 15239 | Y16: 15524 | Z16: 15860 | AA16: 16100 | AB16: 16240 | AC16: 16323 | AD16: 16810 | AE16: 16950 | AF16: 17111 | AG16: 17193 | AH16: 17491 | AI16: 17671 | AJ16: 17761 | AK16: 18053
A17: Solar Rooftop | B17: MW | C17: 7833 | D17: 8514 | E17: 9190 | F17: 9888 | G17: 10549 | H17: 11173 | I17: 11739 | J17: 12303 | K17: 12805 | L17: 13321 | M17: 13860 | N17: 14476 | O17: 15111 | P17: 15656 | Q17: 16202 | R17: 16748 | S17: 17294 | T17: 17840 | U17: 18385 | V17: 18931 | W17: 19477 | X17: 20023 | Y17: 20569 | Z17: 21115 | AA17: 21660 | AB17: 22206 | AC17: 22752 | AD17: 23298 | AE17: 23844 | AF17: 24389 | AG17: 24844 | AH17: 25299 | AI17: 25754 | AJ17: 26209 | AK17: 26664
A18: NSG | B18: MW | C18: 274 | D18: 274 | E18: 274 | F18: 275 | G18: 275 | H18: 275 | I18: 275 | J18: 276 | K18: 276 | L18: 276 | M18: 274 | N18: 272 | O18: 272 | P18: 272 | Q18: 272 | R18: 272 | S18: 272 | T18: 272 | U18: 272 | V18: 272 | W18: 272 | X18: 272 | Y18: 272 | Z18: 272 | AA18: 272 | AB18: 272 | AC18: 272 | AD18: 272 | AE18: 272 | AF18: 272 | AG18: 272 | AH18: 272 | AI18: 272 | AJ18: 272 | AK18: 272
A19: Utility Batteries (<=4h) | B19: MW | C19: 1235 | D19: 3708 | E19: 4671 | F19: 4671 | G19: 5111 | H19: 5551 | I19: 6221 | J19: 7126 | K19: 7286 | L19: 7446 | M19: 7606 | N19: 8277 | O19: 8277 | P19: 8777 | Q19: 9177 | R19: 9177 | S19: 9177 | T19: 9227 | U19: 9617 | V19: 9417 | W19: 9417 | X19: 9487 | Y19: 8599 | Z19: 8756 | AA19: 8316 | AB19: 7876 | AC19: 7206 | AD19: 6401 | AE19: 6241 | AF19: 6081 | AG19: 5921 | AH19: 5921 | AI19: 5921 | AJ19: 5921 | AK19: 5921
A20: Distributed Batteries | B20: MW | C20: 1176 | D20: 1887 | E20: 2348 | F20: 2752 | G20: 3097 | H20: 3383 | I20: 3678 | J20: 3987 | K20: 4288 | L20: 4596 | M20: 4915 | N20: 5248 | O20: 5584 | P20: 5918 | Q20: 6235 | R20: 6559 | S20: 6890 | T20: 7219 | U20: 7539 | V20: 7874 | W20: 8226 | X20: 8593 | Y20: 8968 | Z20: 9328 | AA20: 9679 | AB20: 10011 | AC20: 10344 | AD20: 10673 | AE20: 10990 | AF20: 11318 | AG20: 11647 | AH20: 11978 | AI20: 12312 | AJ20: 12646 | AK20: 12983
A21: Medium Storage (>4-16h) | B21: MW | C21: 240 | D21: 579 | E21: 854 | F21: 1279 | G21: 1479 | H21: 1806 | I21: 2006 | J21: 3049 | K21: 3249 | L21: 3451 | M21: 3451 | N21: 3451 | O21: 3451 | P21: 3451 | Q21: 3952 | R21: 3952 | S21: 3952 | T21: 3952 | U21: 4452 | V21: 4452 | W21: 4452 | X21: 4452 | Y21: 4213 | Z21: 3813 | AA21: 3813 | AB21: 3685 | AC21: 3685 | AD21: 3943 | AE21: 4193 | AF21: 4193 | AG21: 4193 | AH21: 4193 | AI21: 4193 | AJ21: 4193 | AK21: 4193
A22: Deep Storage (>16h) | B22: MW | C22: 900 | D22: 900 | E22: 900 | F22: 900 | G22: 1920 | H22: 2940 | I22: 2940 | J22: 2940 | K22: 2940 | L22: 2940 | M22: 2940 | N22: 2940 | O22: 2940 | P22: 2940 | Q22: 3440 | R22: 3440 | S22: 3440 | T22: 3440 | U22: 3440 | V22: 3440 | W22: 3440 | X22: 3440 | Y22: 3440 | Z22: 3440 | AA22: 3440 | AB22: 3440 | AC22: 3440 | AD22: 3440 | AE22: 3440 | AF22: 3440 | AG22: 3440 | AH22: 3440 | AI22: 3440 | AJ22: 3440 | AK22: 3440
A23: Coal retirement | D23: =D11-C11 -> 0 | E23: =E11-D11 -> -1440 | F23: =F11-E11 -> -1440 | G23: =G11-F11 -> 0 | H23: =H11-G11 -> 0 | I23: =I11-H11 -> -1320 | J23: =J11-I11 -> -1360 | K23: =K11-J11 -> -1360 | ... AK23: =AK11-AJ11 -> 0
A25: QLD
A26: Coal | B26: MW | C26: 8165 | D26: 8119 | E26: 8119 | F26: 6439 | G26: 6439 | H26: 6439 | I26: 5739 | J26: 5739 | K26: 4339 | L26: 3609 | M26: 2879 | N26: 2879 | O26: 2436 | P26: 2436 | Q26: 2016 | R26: 1596 | S26: 1596 | T26: 852 | U26: 852 | V26: 0 | W26: 0 | X26: 0 | Y26: 0 | Z26: 0 | AA26: 0 | AB26: 0 | AC26: 0 | AD26: 0 | AE26: 0 | AF26: 0 | AG26: 0 | AH26: 0 | AI26: 0 | AJ26: 0 | AK26: 0
A27: Hydro | B27: MW | C27: 152 | D27: 152 | E27: 152 | F27: 152 | G27: 152 | H27: 152 | I27: 152 | J27: 152 | K27: 152 | L27: 152 | M27: 152 | N27: 152 | O27: 152 | P27: 152 | Q27: 152 | R27: 152 | S27: 152 | T27: 152 | U27: 152 | V27: 152 | W27: 152 | X27: 152 | Y27: 152 | Z27: 152 | AA27: 152 | AB27: 152 | AC27: 152 | AD27: 152 | AE27: 152 | AF27: 152 | AG27: 152 | AH27: 152 | AI27: 152 | AJ27: 152 | AK27: 152
A28: Gas | B28: MW | C28: 3016 | D28: 3016 | E28: 3016 | F28: 3016 | G28: 3416 | H28: 3416 | I28: 3416 | J28: 3816 | K28: 4376 | L28: 4642 | M28: 4842 | N28: 4672 | O28: 4672 | P28: 4672 | Q28: 4728 | R28: 4728 | S28: 4728 | T28: 5128 | U28: 5128 | V28: 5128 | W28: 5126 | X28: 5127 | Y28: 5127 | Z28: 5327 | AA28: 5808 | AB28: 5468 | AC28: 5468 | AD28: 5468 | AE28: 5468 | AF28: 5468 | AG28: 5468 | AH28: 5468 | AI28: 5468 | AJ28: 5468 | AK28: 5468
A29: Liquid Fuel | B29: MW | C29: 419 | D29: 419 | E29: 419 | F29: 419 | G29: 419 | H29: 419 | I29: 419 | J29: 419 | K29: 131 | L29: 131 | M29: 131 | N29: 131 | O29: 131 | P29: 131 | Q29: 131 | R29: 131 | S29: 131 | T29: 131 | U29: 131 | V29: 0 | W29: 0 | X29: 0 | Y29: 0 | Z29: 0 | AA29: 0 | AB29: 0 | AC29: 0 | AD29: 0 | AE29: 0 | AF29: 0 | AG29: 0 | AH29: 0 | AI29: 0 | AJ29: 0 | AK29: 0
A30: Wind | B30: MW | C30: 2400 | D30: 2652 | E30: 3619 | F30: 3819 | G30: 5078 | H30: 6242 | I30: 7092 | J30: 7482 | K30: 8942 | L30: 9642 | M30: 10666 | N30: 11586 | O30: 12366 | P30: 12636 | Q30: 13656 | R30: 14616 | S30: 14746 | T30: 15916 | U30: 15916 | V30: 16616 | W30: 17246 | X30: 17326 | Y30: 17326 | Z30: 17676 | AA30: 17676 | AB30: 17786 | AC30: 17786 | AD30: 17986 | AE30: 17986 | AF30: 18136 | AG30: 18186 | AH30: 18226 | AI30: 18226 | AJ30: 18276 | AK30: 18276
A31: Solar | B31: MW | C31: 3994 | D31: 4418 | E31: 4771 | F31: 4790 | G31: 5424 | H31: 5499 | I31: 5566 | J31: 5739 | K31: 6252 | L31: 8163 | M31: 9136 | N31: 9769 | O31: 10615 | P31: 11156 | Q31: 11804 | R31: 12760 | S31: 13012 | T31: 14032 | U31: 15298 | V31: 16463 | W31: 16894 | X31: 17425 | Y31: 18041 | Z31: 18366 | AA31: 18537 | AB31: 18908 | AC31: 18974 | AD31: 19050 | AE31: 19271 | AF31: 19541 | AG31: 19807 | AH31: 20003 | AI31: 20194 | AJ31: 20265 | AK31: 20339
